INFO:    Using cached SIF image
INFO:    gocryptfs not found, will not be able to use gocryptfs
INFO:    Using cached SIF image
INFO:    gocryptfs not found, will not be able to use gocryptfs
INFO:    Using cached SIF image
INFO:    gocryptfs not found, will not be able to use gocryptfs
INFO:    Using cached SIF image
INFO:    gocryptfs not found, will not be able to use gocryptfs
INFO:    Using cached SIF image
INFO:    Using cached SIF image
INFO:    gocryptfs not found, will not be able to use gocryptfs
INFO:    gocryptfs not found, will not be able to use gocryptfs
INFO:    Using cached SIF image
INFO:    gocryptfs not found, will not be able to use gocryptfs
INFO:    Using cached SIF image
INFO:    gocryptfs not found, will not be able to use gocryptfs
/usr/local/lib/python3.12/site-packages/ufl_legacy/__init__.py:243: UserWarning: pkg_resources is deprecated as an API. See https://setuptools.pypa.io/en/latest/pkg_resources.html. The pkg_resources package is slated for removal as early as 2025-11-30. Refrain from using this package or pin to Setuptools<81.
  import pkg_resources
/usr/local/lib/python3.12/site-packages/ufl_legacy/__init__.py:243: UserWarning: pkg_resources is deprecated as an API. See https://setuptools.pypa.io/en/latest/pkg_resources.html. The pkg_resources package is slated for removal as early as 2025-11-30. Refrain from using this package or pin to Setuptools<81.
  import pkg_resources
/usr/local/lib/python3.12/site-packages/ufl_legacy/__init__.py:243: UserWarning: pkg_resources is deprecated as an API. See https://setuptools.pypa.io/en/latest/pkg_resources.html. The pkg_resources package is slated for removal as early as 2025-11-30. Refrain from using this package or pin to Setuptools<81.
  import pkg_resources
/usr/local/lib/python3.12/site-packages/ufl_legacy/__init__.py:243: UserWarning: pkg_resources is deprecated as an API. See https://setuptools.pypa.io/en/latest/pkg_resources.html. The pkg_resources package is slated for removal as early as 2025-11-30. Refrain from using this package or pin to Setuptools<81.
  import pkg_resources
/usr/local/lib/python3.12/site-packages/ufl_legacy/__init__.py:243: UserWarning: pkg_resources is deprecated as an API. See https://setuptools.pypa.io/en/latest/pkg_resources.html. The pkg_resources package is slated for removal as early as 2025-11-30. Refrain from using this package or pin to Setuptools<81.
  import pkg_resources
/usr/local/lib/python3.12/site-packages/ufl_legacy/__init__.py:243: UserWarning: pkg_resources is deprecated as an API. See https://setuptools.pypa.io/en/latest/pkg_resources.html. The pkg_resources package is slated for removal as early as 2025-11-30. Refrain from using this package or pin to Setuptools<81.
  import pkg_resources
/usr/local/lib/python3.12/site-packages/ufl_legacy/__init__.py:243: UserWarning: pkg_resources is deprecated as an API. See https://setuptools.pypa.io/en/latest/pkg_resources.html. The pkg_resources package is slated for removal as early as 2025-11-30. Refrain from using this package or pin to Setuptools<81.
  import pkg_resources
/usr/local/lib/python3.12/site-packages/ufl_legacy/__init__.py:243: UserWarning: pkg_resources is deprecated as an API. See https://setuptools.pypa.io/en/latest/pkg_resources.html. The pkg_resources package is slated for removal as early as 2025-11-30. Refrain from using this package or pin to Setuptools<81.
  import pkg_resources
/usr/local/lib/python3.12/site-packages/block/__init__.py:15: UserWarning: The cbc.block repository has moved to https://github.com/blocknics/cbc.block
  warnings.warn('The cbc.block repository has moved to https://github.com/blocknics/cbc.block', UserWarning)
/usr/local/lib/python3.12/site-packages/block/__init__.py:15: UserWarning: The cbc.block repository has moved to https://github.com/blocknics/cbc.block
  warnings.warn('The cbc.block repository has moved to https://github.com/blocknics/cbc.block', UserWarning)
/usr/local/lib/python3.12/site-packages/block/__init__.py:15: UserWarning: The cbc.block repository has moved to https://github.com/blocknics/cbc.block
  warnings.warn('The cbc.block repository has moved to https://github.com/blocknics/cbc.block', UserWarning)
/usr/local/lib/python3.12/site-packages/block/__init__.py:15: UserWarning: The cbc.block repository has moved to https://github.com/blocknics/cbc.block
  warnings.warn('The cbc.block repository has moved to https://github.com/blocknics/cbc.block', UserWarning)
/usr/local/lib/python3.12/site-packages/block/__init__.py:15: UserWarning: The cbc.block repository has moved to https://github.com/blocknics/cbc.block
  warnings.warn('The cbc.block repository has moved to https://github.com/blocknics/cbc.block', UserWarning)
/usr/local/lib/python3.12/site-packages/block/__init__.py:15: UserWarning: The cbc.block repository has moved to https://github.com/blocknics/cbc.block
  warnings.warn('The cbc.block repository has moved to https://github.com/blocknics/cbc.block', UserWarning)
/usr/local/lib/python3.12/site-packages/block/__init__.py:15: UserWarning: The cbc.block repository has moved to https://github.com/blocknics/cbc.block
  warnings.warn('The cbc.block repository has moved to https://github.com/blocknics/cbc.block', UserWarning)
/usr/local/lib/python3.12/site-packages/block/__init__.py:15: UserWarning: The cbc.block repository has moved to https://github.com/blocknics/cbc.block
  warnings.warn('The cbc.block repository has moved to https://github.com/blocknics/cbc.block', UserWarning)
Traceback (most recent call last):
  File "/work2/10756/piercezhang9871/stampede3/3d-1d/study_calibrate.py", line 106, in build_test_graph
Traceback (most recent call last):
Traceback (most recent call last):
  File "/work2/10756/piercezhang9871/stampede3/3d-1d/study_calibrate.py", line 106, in build_test_graph
  File "/work2/10756/piercezhang9871/stampede3/3d-1d/study_calibrate.py", line 106, in build_test_graph
Traceback (most recent call last):
  File "/work2/10756/piercezhang9871/stampede3/3d-1d/study_calibrate.py", line 106, in build_test_graph
Traceback (most recent call last):
  File "/work2/10756/piercezhang9871/stampede3/3d-1d/study_calibrate.py", line 106, in build_test_graph
Traceback (most recent call last):
  File "/work2/10756/piercezhang9871/stampede3/3d-1d/study_calibrate.py", line 106, in build_test_graph
Traceback (most recent call last):
  File "/work2/10756/piercezhang9871/stampede3/3d-1d/study_calibrate.py", line 106, in build_test_graph
    G.make_mesh(num_nodes_exp=TEST_NUM_NODES_EXP)
TypeError: FenicsGraph.make_mesh() got an unexpected keyword argument 'num_nodes_exp'

During handling of the above exception, another exception occurred:

Traceback (most recent call last):
  File "/work2/10756/piercezhang9871/stampede3/3d-1d/study_calibrate.py", line 359, in <module>
Traceback (most recent call last):
  File "/work2/10756/piercezhang9871/stampede3/3d-1d/study_calibrate.py", line 106, in build_test_graph
    G.make_mesh(num_nodes_exp=TEST_NUM_NODES_EXP)
    G.make_mesh(num_nodes_exp=TEST_NUM_NODES_EXP)
    G.make_mesh(num_nodes_exp=TEST_NUM_NODES_EXP)
    G.make_mesh(num_nodes_exp=TEST_NUM_NODES_EXP)
TypeError: FenicsGraph.make_mesh() got an unexpected keyword argument 'num_nodes_exp'

During handling of the above exception, another exception occurred:

Traceback (most recent call last):
  File "/work2/10756/piercezhang9871/stampede3/3d-1d/study_calibrate.py", line 359, in <module>
TypeError: FenicsGraph.make_mesh() got an unexpected keyword argument 'num_nodes_exp'

TypeError: FenicsGraph.make_mesh() got an unexpected keyword argument 'num_nodes_exp'

During handling of the above exception, another exception occurred:

Traceback (most recent call last):
  File "/work2/10756/piercezhang9871/stampede3/3d-1d/study_calibrate.py", line 359, in <module>
During handling of the above exception, another exception occurred:

Traceback (most recent call last):
  File "/work2/10756/piercezhang9871/stampede3/3d-1d/study_calibrate.py", line 359, in <module>
TypeError: FenicsGraph.make_mesh() got an unexpected keyword argument 'num_nodes_exp'

During handling of the above exception, another exception occurred:

Traceback (most recent call last):
  File "/work2/10756/piercezhang9871/stampede3/3d-1d/study_calibrate.py", line 359, in <module>
    G.make_mesh(num_nodes_exp=TEST_NUM_NODES_EXP)
    G.make_mesh(num_nodes_exp=TEST_NUM_NODES_EXP)
TypeError: FenicsGraph.make_mesh() got an unexpected keyword argument 'num_nodes_exp'
TypeError: FenicsGraph.make_mesh() got an unexpected keyword argument 'num_nodes_exp'


During handling of the above exception, another exception occurred:

Traceback (most recent call last):
During handling of the above exception, another exception occurred:

Traceback (most recent call last):
  File "/work2/10756/piercezhang9871/stampede3/3d-1d/study_calibrate.py", line 359, in <module>
  File "/work2/10756/piercezhang9871/stampede3/3d-1d/study_calibrate.py", line 359, in <module>
    main()
    G.make_mesh(num_nodes_exp=TEST_NUM_NODES_EXP)
  File "/work2/10756/piercezhang9871/stampede3/3d-1d/study_calibrate.py", line 169, in main
TypeError: FenicsGraph.make_mesh() got an unexpected keyword argument 'num_nodes_exp'

During handling of the above exception, another exception occurred:

Traceback (most recent call last):
  File "/work2/10756/piercezhang9871/stampede3/3d-1d/study_calibrate.py", line 359, in <module>
    main()
  File "/work2/10756/piercezhang9871/stampede3/3d-1d/study_calibrate.py", line 169, in main
    main()
    main()
    main()
  File "/work2/10756/piercezhang9871/stampede3/3d-1d/study_calibrate.py", line 169, in main
    G = build_test_graph()
  File "/work2/10756/piercezhang9871/stampede3/3d-1d/study_calibrate.py", line 169, in main
  File "/work2/10756/piercezhang9871/stampede3/3d-1d/study_calibrate.py", line 169, in main
        ^^^^^^^^^^^^^^^^^^
  File "/work2/10756/piercezhang9871/stampede3/3d-1d/study_calibrate.py", line 108, in build_test_graph
    main()
    main()
  File "/work2/10756/piercezhang9871/stampede3/3d-1d/study_calibrate.py", line 169, in main
  File "/work2/10756/piercezhang9871/stampede3/3d-1d/study_calibrate.py", line 169, in main
    G = build_test_graph()
    G = build_test_graph()
    main()
        ^^^^^^^^^^^^^^^^^^
    G = build_test_graph()
  File "/work2/10756/piercezhang9871/stampede3/3d-1d/study_calibrate.py", line 108, in build_test_graph
    G.make_mesh(n=TEST_NUM_NODES_EXP)
  File "/work2/10756/piercezhang9871/stampede3/3d-1d/study_calibrate.py", line 169, in main
    G = build_test_graph()
        ^^^^^^^^^^^^^^^^^^
        ^^^^^^^^^^^^^^^^^^
  File "/work2/10756/piercezhang9871/stampede3/3d-1d/study_calibrate.py", line 108, in build_test_graph
  File "/work2/10756/piercezhang9871/stampede3/3d-1d/study_calibrate.py", line 108, in build_test_graph
  File "/usr/local/lib/python3.12/site-packages/graphnics/fenics_graph.py", line 121, in make_mesh
    G = build_test_graph()
        ^^^^^^^^^^^^^^^^^^
    G = build_test_graph()
  File "/work2/10756/piercezhang9871/stampede3/3d-1d/study_calibrate.py", line 108, in build_test_graph
        ^^^^^^^^^^^^^^^^^^
        ^^^^^^^^^^^^^^^^^^
  File "/work2/10756/piercezhang9871/stampede3/3d-1d/study_calibrate.py", line 108, in build_test_graph
    G.make_mesh(n=TEST_NUM_NODES_EXP)
  File "/work2/10756/piercezhang9871/stampede3/3d-1d/study_calibrate.py", line 108, in build_test_graph
  File "/usr/local/lib/python3.12/site-packages/graphnics/fenics_graph.py", line 121, in make_mesh
    G = build_test_graph()
    G.make_mesh(n=TEST_NUM_NODES_EXP)
    G.make_mesh(n=TEST_NUM_NODES_EXP)
  File "/usr/local/lib/python3.12/site-packages/graphnics/fenics_graph.py", line 121, in make_mesh
  File "/usr/local/lib/python3.12/site-packages/graphnics/fenics_graph.py", line 121, in make_mesh
        ^^^^^^^^^^^^^^^^^^
  File "/work2/10756/piercezhang9871/stampede3/3d-1d/study_calibrate.py", line 108, in build_test_graph
    G.make_mesh(n=TEST_NUM_NODES_EXP)
    G.make_mesh(n=TEST_NUM_NODES_EXP)
    G.make_mesh(n=TEST_NUM_NODES_EXP)
  File "/usr/local/lib/python3.12/site-packages/graphnics/fenics_graph.py", line 121, in make_mesh
  File "/usr/local/lib/python3.12/site-packages/graphnics/fenics_graph.py", line 121, in make_mesh
  File "/usr/local/lib/python3.12/site-packages/graphnics/fenics_graph.py", line 121, in make_mesh
    G.make_mesh(n=TEST_NUM_NODES_EXP)
  File "/usr/local/lib/python3.12/site-packages/graphnics/fenics_graph.py", line 121, in make_mesh
    mesh, mf = self.get_mesh(n)
               ^^^^^^^^^^^^^^^^
  File "/usr/local/lib/python3.12/site-packages/graphnics/fenics_graph.py", line 96, in get_mesh
    mesh, mf = self.get_mesh(n)
    mesh = refine(mesh)
    mesh, mf = self.get_mesh(n)
               ^^^^^^^^^^^^^^^^
  File "/usr/local/lib/python3.12/site-packages/graphnics/fenics_graph.py", line 96, in get_mesh
    mesh, mf = self.get_mesh(n)
           ^^^^^^^^^^^^
RuntimeError: 

*** -------------------------------------------------------------------------
*** DOLFIN encountered an error. If you are not able to resolve this issue
*** using the information listed below, you can ask for help at
***
***     https://fenicsproject.discourse.group/
***
*** Remember to include the error message listed below and, if possible,
*** include a *minimal* running example to reproduce the error.
***
*** -------------------------------------------------------------------------
*** Error:   Unable to get shared mesh entities.
*** Reason:  Shared mesh entities have not been computed for dim 1.
*** Where:   This error was encountered inside MeshTopology.cpp.
*** Process: 4
*** 
*** DOLFIN version: 2019.2.0.dev0
*** Git changeset:  a8dcf753d3ab9ae19d7bedf8c634a4fe545032d2
*** -------------------------------------------------------------------------

    mesh, mf = self.get_mesh(n)
               ^^^^^^^^^^^^^^^^
  File "/usr/local/lib/python3.12/site-packages/graphnics/fenics_graph.py", line 96, in get_mesh
               ^^^^^^^^^^^^^^^^
  File "/usr/local/lib/python3.12/site-packages/graphnics/fenics_graph.py", line 96, in get_mesh
    mesh, mf = self.get_mesh(n)
    mesh, mf = self.get_mesh(n)
               ^^^^^^^^^^^^^^^^
    mesh = refine(mesh)
  File "/usr/local/lib/python3.12/site-packages/graphnics/fenics_graph.py", line 96, in get_mesh
               ^^^^^^^^^^^^^^^^
  File "/usr/local/lib/python3.12/site-packages/graphnics/fenics_graph.py", line 96, in get_mesh
           ^^^^^^^^^^^^
               ^^^^^^^^^^^^^^^^
  File "/usr/local/lib/python3.12/site-packages/graphnics/fenics_graph.py", line 96, in get_mesh
    mesh = refine(mesh)
    mesh = refine(mesh)
    mesh, mf = self.get_mesh(n)
RuntimeError: 

*** -------------------------------------------------------------------------
*** DOLFIN encountered an error. If you are not able to resolve this issue
*** using the information listed below, you can ask for help at
***
***     https://fenicsproject.discourse.group/
***
*** Remember to include the error message listed below and, if possible,
*** include a *minimal* running example to reproduce the error.
***
*** -------------------------------------------------------------------------
*** Error:   Unable to get shared mesh entities.
*** Reason:  Shared mesh entities have not been computed for dim 1.
*** Where:   This error was encountered inside MeshTopology.cpp.
*** Process: 7
*** 
*** DOLFIN version: 2019.2.0.dev0
*** Git changeset:  a8dcf753d3ab9ae19d7bedf8c634a4fe545032d2
*** -------------------------------------------------------------------------

           ^^^^^^^^^^^^
               ^^^^^^^^^^^^^^^^
  File "/usr/local/lib/python3.12/site-packages/graphnics/fenics_graph.py", line 96, in get_mesh
    mesh = refine(mesh)
           ^^^^^^^^^^^^
RuntimeError: 

*** -------------------------------------------------------------------------
*** DOLFIN encountered an error. If you are not able to resolve this issue
*** using the information listed below, you can ask for help at
***
***     https://fenicsproject.discourse.group/
***
*** Remember to include the error message listed below and, if possible,
*** include a *minimal* running example to reproduce the error.
***
*** -------------------------------------------------------------------------
*** Error:   Unable to get shared mesh entities.
*** Reason:  Shared mesh entities have not been computed for dim 1.
*** Where:   This error was encountered inside MeshTopology.cpp.
*** Process: 2
*** 
*** DOLFIN version: 2019.2.0.dev0
*** Git changeset:  a8dcf753d3ab9ae19d7bedf8c634a4fe545032d2
*** -------------------------------------------------------------------------

RuntimeError: 

*** -------------------------------------------------------------------------
*** DOLFIN encountered an error. If you are not able to resolve this issue
*** using the information listed below, you can ask for help at
***
***     https://fenicsproject.discourse.group/
***
*** Remember to include the error message listed below and, if possible,
*** include a *minimal* running example to reproduce the error.
***
*** -------------------------------------------------------------------------
*** Error:   Unable to get shared mesh entities.
*** Reason:  Shared mesh entities have not been computed for dim 1.
*** Where:   This error was encountered inside MeshTopology.cpp.
*** Process: 3
*** 
*** DOLFIN version: 2019.2.0.dev0
*** Git changeset:  a8dcf753d3ab9ae19d7bedf8c634a4fe545032d2
*** -------------------------------------------------------------------------

    mesh = refine(mesh)
           ^^^^^^^^^^^^
RuntimeError: 

*** -------------------------------------------------------------------------
*** DOLFIN encountered an error. If you are not able to resolve this issue
*** using the information listed below, you can ask for help at
***
***     https://fenicsproject.discourse.group/
***
*** Remember to include the error message listed below and, if possible,
*** include a *minimal* running example to reproduce the error.
***
*** -------------------------------------------------------------------------
*** Error:   Unable to get shared mesh entities.
*** Reason:  Shared mesh entities have not been computed for dim 1.
*** Where:   This error was encountered inside MeshTopology.cpp.
*** Process: 1
*** 
*** DOLFIN version: 2019.2.0.dev0
*** Git changeset:  a8dcf753d3ab9ae19d7bedf8c634a4fe545032d2
*** -------------------------------------------------------------------------

    mesh = refine(mesh)
           ^^^^^^^^^^^^
RuntimeError: 

*** -------------------------------------------------------------------------
*** DOLFIN encountered an error. If you are not able to resolve this issue
*** using the information listed below, you can ask for help at
***
***     https://fenicsproject.discourse.group/
***
*** Remember to include the error message listed below and, if possible,
*** include a *minimal* running example to reproduce the error.
***
*** -------------------------------------------------------------------------
*** Error:   Unable to get shared mesh entities.
*** Reason:  Shared mesh entities have not been computed for dim 1.
*** Where:   This error was encountered inside MeshTopology.cpp.
*** Process: 6
*** 
*** DOLFIN version: 2019.2.0.dev0
*** Git changeset:  a8dcf753d3ab9ae19d7bedf8c634a4fe545032d2
*** -------------------------------------------------------------------------

           ^^^^^^^^^^^^
RuntimeError: 

*** -------------------------------------------------------------------------
*** DOLFIN encountered an error. If you are not able to resolve this issue
*** using the information listed below, you can ask for help at
***
***     https://fenicsproject.discourse.group/
***
*** Remember to include the error message listed below and, if possible,
*** include a *minimal* running example to reproduce the error.
***
*** -------------------------------------------------------------------------
*** Error:   Unable to get shared mesh entities.
*** Reason:  Shared mesh entities have not been computed for dim 1.
*** Where:   This error was encountered inside MeshTopology.cpp.
*** Process: 0
*** 
*** DOLFIN version: 2019.2.0.dev0
*** Git changeset:  a8dcf753d3ab9ae19d7bedf8c634a4fe545032d2
*** -------------------------------------------------------------------------

    mesh = refine(mesh)
           ^^^^^^^^^^^^
RuntimeError: 

*** -------------------------------------------------------------------------
*** DOLFIN encountered an error. If you are not able to resolve this issue
*** using the information listed below, you can ask for help at
***
***     https://fenicsproject.discourse.group/
***
*** Remember to include the error message listed below and, if possible,
*** include a *minimal* running example to reproduce the error.
***
*** -------------------------------------------------------------------------
*** Error:   Unable to get shared mesh entities.
*** Reason:  Shared mesh entities have not been computed for dim 1.
*** Where:   This error was encountered inside MeshTopology.cpp.
*** Process: 5
*** 
*** DOLFIN version: 2019.2.0.dev0
*** Git changeset:  a8dcf753d3ab9ae19d7bedf8c634a4fe545032d2
*** -------------------------------------------------------------------------

srun: error: c454-001: tasks 0-7: Exited with exit code 1
