No PMIx server was reachable, but a PMI1/2 was detected.
If srun is being used to launch application,  4 singletons will be started.
Traceback (most recent call last):
  File "/scratch/pzz1/3d-1d/sweeper_parallel.py", line 26, in <module>
    import fem
  File "/scratch/pzz1/3d-1d/./src/fem/__init__.py", line 1, in <module>
    from .sink import Sink
  File "/scratch/pzz1/3d-1d/./src/fem/sink.py", line 2, in <module>
    from tissue import AveragingRadius
  File "/scratch/pzz1/3d-1d/./src/tissue/__init__.py", line 3, in <module>
    from .domain_build import DomainBuild
  File "/scratch/pzz1/3d-1d/./src/tissue/domain_build.py", line 2, in <module>
    from dolfin import SubDomain, MeshFunction, Measure, UnitCubeMesh, facets, near, UserExpression
  File "/home/pzz1/.conda/envs/cmor_mdanderson/lib/python3.10/site-packages/dolfin/__init__.py", line 34, in <module>
    from .cpp import __version__
ImportError: /opt/apps/xalt/default/lib64/libcrypto.so: version `OPENSSL_3.3.0' not found (required by /home/pzz1/.conda/envs/cmor_mdanderson/lib/python3.10/site-packages/dolfin/../../.././././libssl.so.3)
srun: error: bb3u19c1: task 0: Exited with exit code 1
/home/pzz1/.conda/envs/cmor_mdanderson/lib/python3.10/site-packages/block/__init__.py:15: UserWarning: The cbc.block repository has moved to https://github.com/blocknics/cbc.block
  warnings.warn('The cbc.block repository has moved to https://github.com/blocknics/cbc.block', UserWarning)
/home/pzz1/.conda/envs/cmor_mdanderson/lib/python3.10/site-packages/block/__init__.py:15: UserWarning: The cbc.block repository has moved to https://github.com/blocknics/cbc.block
  warnings.warn('The cbc.block repository has moved to https://github.com/blocknics/cbc.block', UserWarning)
/home/pzz1/.conda/envs/cmor_mdanderson/lib/python3.10/site-packages/block/__init__.py:15: UserWarning: The cbc.block repository has moved to https://github.com/blocknics/cbc.block
  warnings.warn('The cbc.block repository has moved to https://github.com/blocknics/cbc.block', UserWarning)
Averaging over 224 cells:   0%|          | 0/224 [00:00<?, ?it/s]Averaging over 224 cells: 100%|██████████| 224/224 [00:00<00:00, 3379.44it/s]
Averaging over 224 cells:   0%|          | 0/224 [00:00<?, ?it/s]Averaging over 224 cells: 100%|██████████| 224/224 [00:00<00:00, 3373.02it/s]
Averaging over 224 cells:   0%|          | 0/224 [00:00<?, ?it/s]Averaging over 224 cells: 100%|██████████| 224/224 [00:00<00:00, 3372.81it/s]
Moving new file over differing existing file:
src: /tmp/tmp319sy2_m/libdijitso-ffc_element_4502efb56872ca18cfdb4b763cc7cfa4ed66ed2b.so
dst: /scratch/pzz1/dijitso_cache_1074138_0/lib/libdijitso-ffc_element_4502efb56872ca18cfdb4b763cc7cfa4ed66ed2b.so
backup: /scratch/pzz1/dijitso_cache_1074138_0/lib/libdijitso-ffc_element_4502efb56872ca18cfdb4b763cc7cfa4ed66ed2b.so.old
Moving new file over differing existing file:
src: /tmp/tmph2jm9i1u/libdijitso-ffc_element_3ddcbca72c1d15efdf9974e7811c977e2b01c063.so
dst: /scratch/pzz1/dijitso_cache_1074138_0/lib/libdijitso-ffc_element_3ddcbca72c1d15efdf9974e7811c977e2b01c063.so
backup: /scratch/pzz1/dijitso_cache_1074138_0/lib/libdijitso-ffc_element_3ddcbca72c1d15efdf9974e7811c977e2b01c063.so.old
Moving new file over differing existing file:
src: /tmp/tmp2fmyvg1o/libdijitso-ffc_element_3ddcbca72c1d15efdf9974e7811c977e2b01c063.so
dst: /scratch/pzz1/dijitso_cache_1074138_0/lib/libdijitso-ffc_element_3ddcbca72c1d15efdf9974e7811c977e2b01c063.so
backup: /scratch/pzz1/dijitso_cache_1074138_0/lib/libdijitso-ffc_element_3ddcbca72c1d15efdf9974e7811c977e2b01c063.so.old
Traceback (most recent call last):
  File "/home/pzz1/.conda/envs/cmor_mdanderson/lib/python3.10/shutil.py", line 816, in move
    os.rename(src, real_dst)
FileNotFoundError: [Errno 2] No such file or directory: '/scratch/pzz1/dijitso_cache_1074138_0/lib/libdijitso-ffc_element_3ddcbca72c1d15efdf9974e7811c977e2b01c063.so' -> '/scratch/pzz1/dijitso_cache_1074138_0/lib/libdijitso-ffc_element_3ddcbca72c1d15efdf9974e7811c977e2b01c063.so.old.priv.27507579259710506715108886050185384585'

During handling of the above exception, another exception occurred:

Traceback (most recent call last):
  File "/scratch/pzz1/3d-1d/sweeper_parallel.py", line 197, in <module>
    worker_init(TEST_DOMAIN, LOWER_BOUNDS, UPPER_BOUNDS)
  File "/scratch/pzz1/3d-1d/sweeper_parallel.py", line 79, in worker_init
    SOLVER.solve(
  File "/scratch/pzz1/3d-1d/./src/fem/sub_cubes.py", line 40, in solve
    super().solve(gamma, gamma_a, gamma_R, mu, k_t, P_in, P_cvp)
  File "/scratch/pzz1/3d-1d/./src/fem/velo.py", line 14, in solve
    super().solve(gamma, gamma_a, gamma_R, mu, k_t, P_in, P_cvp)
  File "/scratch/pzz1/3d-1d/./src/fem/sink.py", line 62, in solve
    A, b = map(ii_assemble, (a_forms, L_forms))
  File "/home/pzz1/.conda/envs/cmor_mdanderson/lib/python3.10/site-packages/xii/assembler/xii_assembly.py", line 62, in assemble
    blocks = reshape_list(list(map(assemble, flatten_list(form))), shape)
  File "/home/pzz1/.conda/envs/cmor_mdanderson/lib/python3.10/site-packages/xii/assembler/xii_assembly.py", line 49, in assemble
    tensor = module.assemble_form(form, arity)
  File "/home/pzz1/.conda/envs/cmor_mdanderson/lib/python3.10/site-packages/xii/assembler/average_assembly.py", line 38, in assemble_form
    return assembler.assemble(form, arity)
  File "/home/pzz1/.conda/envs/cmor_mdanderson/lib/python3.10/site-packages/xii/assembler/reduced_assembler.py", line 61, in assemble
    components.append(xii.assembler.xii_assembly.assemble(Form([integral])))
  File "/home/pzz1/.conda/envs/cmor_mdanderson/lib/python3.10/site-packages/xii/assembler/xii_assembly.py", line 55, in assemble
    return df.assemble(form)
  File "/home/pzz1/.conda/envs/cmor_mdanderson/lib/python3.10/site-packages/dolfin/fem/assembling.py", line 198, in assemble
    dolfin_form = _create_dolfin_form(form, form_compiler_parameters)
  File "/home/pzz1/.conda/envs/cmor_mdanderson/lib/python3.10/site-packages/dolfin/fem/assembling.py", line 56, in _create_dolfin_form
    return Form(form,
  File "/home/pzz1/.conda/envs/cmor_mdanderson/lib/python3.10/site-packages/dolfin/fem/form.py", line 43, in __init__
    ufc_form = ffc_jit(form, form_compiler_parameters=form_compiler_parameters,
  File "/home/pzz1/.conda/envs/cmor_mdanderson/lib/python3.10/site-packages/dolfin/jit/jit.py", line 47, in mpi_jit
    return local_jit(*args, **kwargs)
  File "/home/pzz1/.conda/envs/cmor_mdanderson/lib/python3.10/site-packages/dolfin/jit/jit.py", line 97, in ffc_jit
    return ffc.jit(ufl_form, parameters=p)
  File "/home/pzz1/.conda/envs/cmor_mdanderson/lib/python3.10/site-packages/ffc/jitcompiler.py", line 217, in jit
    module = jit_build(ufl_object, module_name, parameters)
  File "/home/pzz1/.conda/envs/cmor_mdanderson/lib/python3.10/site-packages/ffc/jitcompiler.py", line 130, in jit_build
    module, signature = dijitso.jit(jitable=ufl_object,
  File "/home/pzz1/.conda/envs/cmor_mdanderson/lib/python3.10/site-packages/dijitso/jit.py", line 165, in jit
    header, source, dependencies = generate(jitable, name, signature, params["generator"])
  File "/home/pzz1/.conda/envs/cmor_mdanderson/lib/python3.10/site-packages/ffc/jitcompiler.py", line 76, in jit_generate
    dep_module_name = jit(dep, parameters, indirect=True)
  File "/home/pzz1/.conda/envs/cmor_mdanderson/lib/python3.10/site-packages/ffc/jitcompiler.py", line 217, in jit
    module = jit_build(ufl_object, module_name, parameters)
  File "/home/pzz1/.conda/envs/cmor_mdanderson/lib/python3.10/site-packages/ffc/jitcompiler.py", line 130, in jit_build
    module, signature = dijitso.jit(jitable=ufl_object,
  File "/home/pzz1/.conda/envs/cmor_mdanderson/lib/python3.10/site-packages/dijitso/jit.py", line 177, in jit
    build_shared_library(signature, header, source, dependencies,
  File "/home/pzz1/.conda/envs/cmor_mdanderson/lib/python3.10/site-packages/dijitso/build.py", line 164, in build_shared_library
    lockfree_move_file(temp_lib_filename, lib_filename)
  File "/home/pzz1/.conda/envs/cmor_mdanderson/lib/python3.10/site-packages/dijitso/system.py", line 248, in lockfree_move_file
    return _lockfree_move_file(src, dst, False)
  File "/home/pzz1/.conda/envs/cmor_mdanderson/lib/python3.10/site-packages/dijitso/system.py", line 282, in _lockfree_move_file
    _lockfree_move_file(dst, backup, True)
  File "/home/pzz1/.conda/envs/cmor_mdanderson/lib/python3.10/site-packages/dijitso/system.py", line 294, in _lockfree_move_file
    move_file(src, priv(ui))
  File "/home/pzz1/.conda/envs/cmor_mdanderson/lib/python3.10/site-packages/dijitso/system.py", line 234, in move_file
    shutil.move(srcfilename, dstfilename)
  File "/home/pzz1/.conda/envs/cmor_mdanderson/lib/python3.10/shutil.py", line 836, in move
    copy_function(src, real_dst)
  File "/home/pzz1/.conda/envs/cmor_mdanderson/lib/python3.10/shutil.py", line 434, in copy2
    copyfile(src, dst, follow_symlinks=follow_symlinks)
  File "/home/pzz1/.conda/envs/cmor_mdanderson/lib/python3.10/shutil.py", line 254, in copyfile
    with open(src, 'rb') as fsrc:
FileNotFoundError: [Errno 2] No such file or directory: '/scratch/pzz1/dijitso_cache_1074138_0/lib/libdijitso-ffc_element_3ddcbca72c1d15efdf9974e7811c977e2b01c063.so'
srun: error: bb3u19c1: task 2: Exited with exit code 1
Moving new file over differing existing file:
src: /tmp/tmpx3tugbqn/libdijitso-ffc_form_062f8982f1fda9d0511506bdea1bc4478b6c9b6e.so
dst: /scratch/pzz1/dijitso_cache_1074138_0/lib/libdijitso-ffc_form_062f8982f1fda9d0511506bdea1bc4478b6c9b6e.so
backup: /scratch/pzz1/dijitso_cache_1074138_0/lib/libdijitso-ffc_form_062f8982f1fda9d0511506bdea1bc4478b6c9b6e.so.old
Moving new file over differing existing file:
src: /tmp/tmpgln1bxql/libdijitso-ffc_form_0e941b02070a5efc079a9ba08ea556e09e114a45.so
dst: /scratch/pzz1/dijitso_cache_1074138_0/lib/libdijitso-ffc_form_0e941b02070a5efc079a9ba08ea556e09e114a45.so
backup: /scratch/pzz1/dijitso_cache_1074138_0/lib/libdijitso-ffc_form_0e941b02070a5efc079a9ba08ea556e09e114a45.so.old
Traceback (most recent call last):
  File "/scratch/pzz1/3d-1d/sweeper_parallel.py", line 206, in <module>
    my_results = [sweep_job(args) for args in jobs]
  File "/scratch/pzz1/3d-1d/sweeper_parallel.py", line 206, in <listcomp>
    my_results = [sweep_job(args) for args in jobs]
  File "/scratch/pzz1/3d-1d/sweeper_parallel.py", line 138, in sweep_job
    upper_in  = SOLVER.compute_upper_cube_flux_in()
  File "/scratch/pzz1/3d-1d/./src/fem/sub_cubes.py", line 63, in compute_upper_cube_flux_in
    return assemble(expr * self.dS_upper(1))
  File "/home/pzz1/.conda/envs/cmor_mdanderson/lib/python3.10/site-packages/dolfin/fem/assembling.py", line 198, in assemble
    dolfin_form = _create_dolfin_form(form, form_compiler_parameters)
  File "/home/pzz1/.conda/envs/cmor_mdanderson/lib/python3.10/site-packages/dolfin/fem/assembling.py", line 56, in _create_dolfin_form
    return Form(form,
  File "/home/pzz1/.conda/envs/cmor_mdanderson/lib/python3.10/site-packages/dolfin/fem/form.py", line 43, in __init__
    ufc_form = ffc_jit(form, form_compiler_parameters=form_compiler_parameters,
  File "/home/pzz1/.conda/envs/cmor_mdanderson/lib/python3.10/site-packages/dolfin/jit/jit.py", line 47, in mpi_jit
    return local_jit(*args, **kwargs)
  File "/home/pzz1/.conda/envs/cmor_mdanderson/lib/python3.10/site-packages/dolfin/jit/jit.py", line 97, in ffc_jit
    return ffc.jit(ufl_form, parameters=p)
  File "/home/pzz1/.conda/envs/cmor_mdanderson/lib/python3.10/site-packages/ffc/jitcompiler.py", line 223, in jit
    raise FFCJitError("A directory with files to reproduce the jit build failure has been created.")
ffc.jitcompiler.FFCJitError: A directory with files to reproduce the jit build failure has been created.
srun: error: bb3u19c1: task 3: Exited with exit code 1
